#priority 970

import crafttweaker.item.IItemStack;

import mods.gregtech.IControllerTile;
import mods.gregtech.recipe.RecipeMap;
import mods.gregtech.recipe.RecipeMaps;
import mods.gregtech.recipe.FactoryRecipeMap;
import mods.gregtech.recipe.RecipeMapBuilder;
import mods.gregtech.recipe.functions.IRunOverclockingLogicFunction;
import mods.gregtech.recipe.IRecipe;
import mods.gregtech.recipe.IRecipeLogic;
import mods.gregtech.multiblock.Builder;
import mods.gregtech.multiblock.FactoryBlockPattern;
import mods.gregtech.multiblock.RelativeDirection;
import mods.gregtech.multiblock.functions.IPatternBuilderFunction;
import mods.gregtech.multiblock.functions.IGetBaseTextureFunction;
import mods.gregtech.multiblock.CTPredicate;
import mods.gregtech.multiblock.IBlockPattern;
import mods.gregtech.multiblock.IIMultiblockPart;
import mods.gregtech.render.ICubeRenderer;
import mods.gregtech.render.MoveType;

########################################
# Multiblock Builder
########################################
# Star forge
########################################
var star_forge = Builder.start("star_forge", 32002)
  .withPattern(function(controller as IControllerTile) as IBlockPattern {
    return FactoryBlockPattern.start()
                .aisle("               ", "      CCC      ", "      C C      ", "      C C      ", "      C C      ", "      C C      ", "      C C      ", "      CCC      ", "               ")
                .aisle("      C C      ", "     FFFFF     ", "               ", "               ", "               ", "               ", "               ", "     FFFFF     ", "      C C      ")
                .aisle("      C C      ", "   FF     FF   ", "               ", "               ", "               ", "               ", "               ", "   FF     FF   ", "      C C      ")
                .aisle("      C C      ", "  F         F  ", "     FFFFF     ", "               ", "               ", "               ", "     FFFFF     ", "  F         F  ", "      C C      ")
                .aisle("      C C      ", "  F         F  ", "    F XXX F    ", "      XXX      ", "      XXX      ", "      XXX      ", "    F XXX F    ", "  F         F  ", "      C C      ")
                .aisle("      C C      ", " F           F ", "   F X   X F   ", "     X   X     ", "     X   X     ", "     X   X     ", "   F X   X F   ", " F           F ", "      C C      ")
                .aisle(" CCCCCCMCCCCCC ", "CF    XXX    FC", "C  FX     XF  C", "C   X     X   C", "C   X     X   C", "C   X     X   C", "C  FX     XF  C", "CF    XXX    FC", " CCCCCCMCCCCCC ")
                .aisle("      MMM      ", "CF    XXX    FC", "   FX     XF   ", "    X     X    ", "    X     X    ", "    X     X    ", "   FX     XF   ", "CF    XXX    FC", "      MMM      ")
                .aisle(" CCCCCCMCCCCCC ", "CF    XXX    FC", "C  FX     XF  C", "C   X     X   C", "C   X     X   C", "C   X     X   C", "C  FX     XF  C", "CF    XXX    FC", " CCCCCCMCCCCCC ")
                .aisle("      C C      ", " F           F ", "   F X   X F   ", "     X   X     ", "     X   X     ", "     X   X     ", "   F X   X F   ", " F           F ", "      C C      ")
                .aisle("      C C      ", "  F         F  ", "    F XXX F    ", "      XXX      ", "      XXX      ", "      XXX      ", "    F XXX F    ", "  F         F  ", "      C C      ")
                .aisle("      C C      ", "  F         F  ", "     FFFFF     ", "               ", "               ", "               ", "     FFFFF     ", "  F         F  ", "      C C      ")
                .aisle("      C C      ", "   FF     FF   ", "               ", "               ", "               ", "               ", "               ", "   FF     FF   ", "      C C      ")
                .aisle("      C C      ", "     FFFFF     ", "               ", "               ", "               ", "               ", "               ", "     FFFFF     ", "      C C      ")
                .aisle("               ", "      CSC      ", "      C C      ", "      C C      ", "      C C      ", "      C C      ", "      C C      ", "      CCC      ", "               ")
                .where('M', CTPredicate.states(<metastate:gregtech:fusion_casing:3>))
                .where('C', CTPredicate.states(<blockstate:htmltech:casing>).setMinGlobalLimited(136) | controller.autoAbilities())
                .where('X', CTPredicate.states(<metastate:gregtech:wire_coil:5>))
                .where('F', CTPredicate.states(<metastate:gregtech:fusion_casing>))
                .where('S', controller.self())
                .where(' ', CTPredicate.getAny())
                .build();
  } as IPatternBuilderFunction)
  .withRecipeMap(star_forge)
  .withBaseTexture(<metastate:gregtech:fusion_casing:1>)
  .buildAndRegister();
star_forge.hasMaintenanceMechanics = true;
star_forge.hasMufflerMechanics = false;